Workbook

Sheet 1. Dashboard
A1: NP App HH - Project Dashboard
A3: PROJECT OVERVIEW
A4: Project name | B4: NP App HH (Phòng khám Nguyên Phương)
A5: Sprint hiện tại | B5: (điền sau khi start)
A6: Period | B6: (điền sau khi start)
A7: Estimated end date | B7: (điền sau khi start)
A9: TASK STATUS (auto-compute từ Tasks tab)
A10: Status | B10: Count | C10: %
A11: Done | B11: =COUNTIF('2. Tasks'!G:G,"Done") -> 0 | C11: =IFERROR(B11/SUM(B$11:B$16),0) -> 0
A12: Doing | B12: =COUNTIF('2. Tasks'!G:G,"Doing") -> 0 | C12: =IFERROR(B12/SUM(B$11:B$16),0) -> 0
A13: Review | B13: =COUNTIF('2. Tasks'!G:G,"Review") -> 0 | C13: =IFERROR(B13/SUM(B$11:B$16),0) -> 0
A14: Ready | B14: =COUNTIF('2. Tasks'!G:G,"Ready") -> 0 | C14: =IFERROR(B14/SUM(B$11:B$16),0) -> 0
A15: Todo | B15: =COUNTIF('2. Tasks'!G:G,"Todo") -> 92 | C15: =IFERROR(B15/SUM(B$11:B$16),0) -> 1
A16: Blocked | B16: =COUNTIF('2. Tasks'!G:G,"Blocked") -> 0 | C16: =IFERROR(B16/SUM(B$11:B$16),0) -> 0
A17: Total tasks | B17: =SUM(B11:B16) -> 92
A19: PRIORITY BREAKDOWN
A20: Priority | B20: Total | C20: Done | D20: %
A21: P0 (critical) | B21: =COUNTIF('2. Tasks'!F:F,"P0") -> 46 | C21: =COUNTIFS('2. Tasks'!F:F,"P0",'2. Tasks'!G:G,"Done") -> 0 | D21: =IFERROR(C21/B21,0) -> 0
A22: P1 (high) | B22: =COUNTIF('2. Tasks'!F:F,"P1") -> 32 | C22: =COUNTIFS('2. Tasks'!F:F,"P1",'2. Tasks'!G:G,"Done") -> 0 | D22: =IFERROR(C22/B22,0) -> 0
A23: P2 (medium) | B23: =COUNTIF('2. Tasks'!F:F,"P2") -> 12 | C23: =COUNTIFS('2. Tasks'!F:F,"P2",'2. Tasks'!G:G,"Done") -> 0 | D23: =IFERROR(C23/B23,0) -> 0
A24: P3 (low) | B24: =COUNTIF('2. Tasks'!F:F,"P3") -> 2 | C24: =COUNTIFS('2. Tasks'!F:F,"P3",'2. Tasks'!G:G,"Done") -> 0 | D24: =IFERROR(C24/B24,0) -> 0
A26: RISKS (auto-compute từ Risks tab)
A27: Active HIGH | B27: =COUNTIFS('5. Risks'!F:F,"HIGH",'5. Risks'!I:I,"Active") -> 3
A28: Active MEDIUM | B28: =COUNTIFS('5. Risks'!F:F,"MEDIUM",'5. Risks'!I:I,"Active") -> 3
A29: Active LOW | B29: =COUNTIFS('5. Risks'!F:F,"LOW",'5. Risks'!I:I,"Active") -> 0
A31: BUGS (auto-compute từ Bugs tab)
A32: Open P0 | B32: =COUNTIFS('4. Bugs'!C:C,"P0",'4. Bugs'!J:J,"<>Closed") -> 0
A33: Open P1 | B33: =COUNTIFS('4. Bugs'!C:C,"P1",'4. Bugs'!J:J,"<>Closed") -> 0
A34: Total open bugs | B34: =COUNTIF('4. Bugs'!J:J,"<>Closed")-COUNTBLANK('4. Bugs'!J:J) -> 2
A36: INTEGRATIONS STATUS
A37: Xem chi tiết tab "7. Integrations"

Sheet 2. Tasks
A1: Task ID | B1: Task name | C1: Module | D1: Spec Ref | E1: Type | F1: Priority | G1: Status | H1: Assignee | I1: Sprint | J1: Estimate (d) | K1: Actual (d) | L1: Depends on | M1: Notes
A2: T-001 | B2: Setup repository + CI/CD pipeline | C2: DevOps | D2: B6 §2.4 | E2: DevOps | F2: P0 | G2: Todo | I2: Sprint 1 | J2: 2 | M2: Git, branch strategy, CI/CD
A3: T-002 | B3: Setup staging + production environments | C3: DevOps | D3: B6 §2.4 | E3: DevOps | F3: P0 | G3: Todo | I3: Sprint 1 | J3: 2 | L3: T-001
A4: T-003 | B4: Database schema design + migrations | C4: DB | D4: B1 §15 | E4: Backend | F4: P0 | G4: Todo | I4: Sprint 1 | J4: 5 | M4: 40+ entities theo B1 entity dictionary
A5: T-004 | B5: Setup ORM + base models | C5: Backend | D5: B1 §15 | E5: Backend | F5: P0 | G5: Todo | I5: Sprint 1 | J5: 2 | L5: T-003
A6: T-005 | B6: Implement Auth: SĐT + OTP API | C6: Auth | D6: B5.2 S-Login §1.7 | E6: Backend | F6: P0 | G6: Todo | I6: Sprint 1 | J6: 4 | L6: T-003, T-009 | M6: Phụ thuộc Zalo OA setup
A7: T-006 | B7: Implement Device Binding logic | C7: Auth | D7: B5.2 S-Login §1.6 | E7: Backend | F7: P0 | G7: Todo | I7: Sprint 2 | J7: 3 | L7: T-005
A8: T-007 | B8: Build login screen 3-step wizard | C8: Auth | D8: B5.2 S-Login §1.4 | E8: Frontend | F8: P0 | G8: Todo | I8: Sprint 2 | J8: 4 | L8: T-005 | M8: Reuse design ref existing
A9: T-008 | B9: Permission middleware base 5 roles | C9: Permission | D9: B4 R-9-1 | E9: Backend | F9: P0 | G9: Todo | I9: Sprint 2 | J9: 4 | L9: T-005
A10: T-009 | B10: Zalo OA SDK integration setup | C10: Integration | D10: B5.2 §1.7 | E10: Backend | F10: P0 | G10: Todo | I10: Sprint 1 | J10: 3 | M10: BLOCKER: Zalo OA chưa setup
A11: T-010 | B11: OTP rate limiting + lock account | C11: Auth | D11: B5.2 §1.8 | E11: Backend | F11: P0 | G11: Todo | I11: Sprint 2 | J11: 2 | L11: T-005 | M11: 3 lần wrong → lock 15p
A12: T-011 | B12: MS-2 Onboarding screen UI + logic | C12: Onboarding | D12: B5.1 MS-2 | E12: Frontend | F12: P1 | G12: Todo | I12: Sprint 2 | J12: 3 | L12: T-007 | M12: Bắt buộc đặt target HH tháng
A13: T-012 | B13: MS-2 API set-target + suggestion | C13: Onboarding | D13: B5.1 MS-2 §1.7 | E13: Backend | F13: P1 | G13: Todo | I13: Sprint 2 | J13: 2 | L13: T-008
A14: T-020 | B14: Order entity + state machine 8 states | C14: Order | D14: B2.2 §1, B4 R-2-1 | E14: Backend | F14: P0 | G14: Todo | I14: Sprint 3 | J14: 4 | L14: T-003
A15: T-021 | B15: Order auto NO_SHOW cron T+30p | C15: Order | D15: B4 R-2-2 | E15: Backend | F15: P1 | G15: Todo | I15: Sprint 3 | J15: 2 | L15: T-020
A16: T-022 | B16: OrderRoleAssignment populate logic at CONFIRMED | C16: HH Engine | D16: B4 R-3-1 | E16: Backend | F16: P0 | G16: Todo | I16: Sprint 3 | J16: 3 | L16: T-020 | M16: 2 row Sale + TC
A17: T-023 | B17: Populate BS row khi exam_started webhook | C17: HH Engine | D17: B4 R-3-2 | E17: Backend | F17: P0 | G17: Todo | I17: Sprint 3 | J17: 3 | L17: T-022, T-040 | M17: Phụ thuộc Isoft webhook
A18: T-024 | B18: Snapshot ranking pattern implementation | C18: HH Engine | D18: B4 R-1-3, R-4-2 | E18: Backend | F18: P0 | G18: Todo | I18: Sprint 3 | J18: 3 | L18: T-022
A19: T-025 | B19: HH formula calculation engine | C19: HH Engine | D19: B4 R-1-1 | E19: Backend | F19: P0 | G19: Todo | I19: Sprint 3 | J19: 4 | L19: T-024 | M19: net_profit = total_paid - total_cost
A20: T-026 | B20: CR lifecycle + state machine | C20: CR | D20: B4 R-2-3 | E20: Backend | F20: P0 | G20: Todo | I20: Sprint 4 | J20: 4 | L20: T-025 | M20: 7 states
A21: T-027 | B21: Refund recompute logic (full + partial) | C21: HH Engine | D21: B4 R-12-7 | E21: Backend | F21: P0 | G21: Todo | I21: Sprint 4 | J21: 3 | L21: T-026 | M21: Recompute all role per R-12-7
A22: T-028 | B22: Order list screen update filter status 8 | C22: Order | D22: B5.3 §4 | E22: Frontend | F22: P1 | G22: Todo | I22: Sprint 4 | J22: 2 | M22: Add REFUND_*, IN_PROGRESS filter
A23: T-029 | B23: Order detail screen update | C23: Order | D23: B5.3 S-Order-Detail | E23: Frontend | F23: P1 | G23: Todo | I23: Sprint 4 | J23: 5 | L23: T-026 | M23: Add khiếu nại CTA, OrderItem.status mark, refund display
A24: T-030 | B24: Order create screen reuse + integration | C24: Order | D24: B5.3 (note) | E24: Frontend | F24: P1 | G24: Todo | I24: Sprint 4 | J24: 3 | L24: T-022 | M24: Reuse existing order-create.tsx
A25: T-031 | B25: MS-1 Tạo đơn thành công screen | C25: Order | D25: B5.5 MS-1 | E25: Frontend | F25: P2 | G25: Todo | I25: Sprint 4 | J25: 2 | L25: T-030
A26: T-040 | B26: Isoft webhook handler base | C26: Integration | D26: B1 §11, B4 R-12-3,4,5 | E26: Backend | F26: P0 | G26: Todo | I26: Sprint 5 | J26: 5 | L26: T-020 | M26: BLOCKER: Isoft contract
A27: T-041 | B27: Webhook idempotency + audit log | C27: Integration | D27: B4 R-12-4 | E27: Backend | F27: P0 | G27: Todo | I27: Sprint 5 | J27: 2 | L27: T-040
A28: T-042 | B28: AdjustmentRequest entity + state machine | C28: Adjustment | D28: B4 R-2-4 | E28: Backend | F28: P0 | G28: Todo | I28: Sprint 5 | J28: 3 | L28: T-026
A29: T-043 | B29: MS-9 Tạo Adjustment screen (KT) | C29: Adjustment | D29: B5.1 MS-9 | E29: Frontend | F29: P1 | G29: Todo | I29: Sprint 5 | J29: 4 | L29: T-042 | M29: Form + preview HH ảnh hưởng
A30: T-044 | B30: MS-9 API tạo + preview-impact | C30: Adjustment | D30: B5.1 MS-9 §2.7 | E30: Backend | F30: P1 | G30: Todo | I30: Sprint 5 | J30: 3 | L30: T-042
A31: T-045 | B31: MS-10 Duyệt Adjustment screen (CEO) | C31: Adjustment | D31: B5.1 MS-10 | E31: Frontend | F31: P1 | G31: Todo | I31: Sprint 5 | J31: 4 | L31: T-042 | M31: Bulk approve + reject flow
A32: T-046 | B32: MS-10 API approve/reject batch | C32: Adjustment | D32: B5.1 MS-10 §3.7 | E32: Backend | F32: P1 | G32: Todo | I32: Sprint 5 | J32: 2 | L32: T-042
A33: T-047 | B33: Adjustment edit window 30 ngày + clawback delta | C33: Adjustment | D33: B4 R-6-3, R-6-4 | E33: Backend | F33: P0 | G33: Todo | I33: Sprint 6 | J33: 4 | L33: T-042 | M33: Critical logic
A34: T-048 | B34: Auto rule framework engine | C34: Auto Rule | D34: B4 R-7-4 | E34: Backend | F34: P1 | G34: Todo | I34: Sprint 6 | J34: 3 | L34: T-042
A35: T-049 | B35: Auto rule "Thưởng target tháng" implementation | C35: Auto Rule | D35: B4 R-7-2 | E35: Backend | F35: P1 | G35: Todo | I35: Sprint 6 | J35: 2 | L35: T-048 | M35: HH gốc × bonus_pct × overshoot
A36: T-050 | B36: MS-6 Cấu hình Auto Rule UI | C36: Auto Rule | D36: B5.4 MS-6 | E36: Frontend | F36: P2 | G36: Todo | I36: Sprint 6 | J36: 3 | L36: T-048
A37: T-051 | B37: SalaryCycle entity + lifecycle | C37: Pay Cycle | D37: B2.4 §7 | E37: Backend | F37: P0 | G37: Todo | I37: Sprint 6 | J37: 3 | L37: T-026 | M37: open/locked/closed states
A38: T-052 | B38: CR khiếu nại flow (NV submit, Diễm review) | C38: CR | D38: B4 R-11-7 | E38: Backend | F38: P1 | G38: Todo | I38: Sprint 6 | J38: 3 | L38: T-026 | M38: 3-day window
A39: T-053 | B39: MS-12 Export Excel screen + 4 file generator | C39: Pay Cycle | D39: B5.1 MS-12 | E39: Frontend | F39: P0 | G39: Todo | I39: Sprint 6 | J39: 4 | L39: T-051
A40: T-054 | B40: MS-12 backend file generation | C40: Pay Cycle | D40: B5.1 MS-12 §4.7 | E40: Backend | F40: P0 | G40: Todo | I40: Sprint 6 | J40: 4 | L40: T-051 | M40: 4 Excel files
...

Sheet 3. Sprints
A1: NP App HH - Sprint Planning
A3: Note: Tasks list trong tab "2. Tasks", filter theo Sprint column.
A5: Sprint | B5: Period | C5: Goal | D5: Key tasks | E5: Demo / Gate | F5: Milestone
A6: Sprint 1 | B6: Tuần 1-2 | C6: Setup + Auth foundation | D6: Repo, CI/CD, DB schema, Auth API, Zalo OA SDK setup | E6: Working login screen | F6: M1
A7: Sprint 2 | B7: Tuần 3-4 | C7: Auth complete + Onboarding | D7: Login wizard, Permission middleware, MS-2 Onboarding | E7: NV có thể login + đặt target | F7: M1
A8: Sprint 3 | B8: Tuần 5-6 | C8: Order lifecycle + HH formula | D8: Order entity, OrderRoleAssignment, snapshot ranking, HH calculation | E8: Tạo đơn → ăn HH end-to-end | F8: M2
A9: Sprint 4 | B9: Tuần 7-8 | C9: CR lifecycle + Order screens | D9: CR state machine, refund logic, Order detail UI, MS-1 success | E9: Demo CR workflow cho anh Nguyên | F9: M2
A10: Sprint 5 | B10: Tuần 9-10 | C10: Adjustment workflow | D10: AdjustmentRequest, MS-9, MS-10, Auto rule framework | E10: Diễm tạo + CEO duyệt adjustment hoạt động | F10: M3
A11: Sprint 6 | B11: Tuần 11-12 | C11: Pay cycle + Income | D11: SalaryCycle, MS-12 Export, S-Income, S-Admin-Commission-Approval, khiếu nại flow | E11: Run 1 cycle hoàn chỉnh với data fake | F11: M3
A12: Sprint 7 | B12: Tuần 13-14 | C12: Isoft webhooks + Reminders | D12: 6 webhook events, reminder schedule, MS-3 Notification | E12: Test integration Isoft staging | F12: M4
A13: Sprint 8 | B13: Tuần 15-16 | C13: Admin screens | D13: S-Admin-Staff rework, S-Admin-Settings 10 sections, recall logic | E13: CEO config full settings | F13: M4
A14: Sprint 9 | B14: Tuần 17-18 | C14: Customer + Shift | D14: MS-7 Customer Follow-up, Shift architecture J, MS-5 | E14: Customer recall + multi-shift ready | F14: M5
A15: Sprint 10 | B15: Tuần 19-20 | C15: Polish + reuse existing | D15: MS-4, MS-8, MS-11, ranking conditional, reuse customer/service/dashboard/analytics | E15: All screens working | F15: M5
A16: Sprint 11 | B16: Tuần 21-22 | C16: Testing | D16: Unit + Integration + E2E + Load + Security tests, UAT | E16: Pass all tests, no P0/P1 bugs | F16: M6
A17: Sprint 12 | B17: Tuần 23-24 | C17: Pilot + Launch | D17: Pilot 2 tuần parallel, training, cutover, go-live, hot-fix monitoring | E17: NP App HH live in production | F17: M6

Sheet 4. Bugs
A1: Bug Tracker - Sẽ populate khi dev start + UAT
A3: Bug ID | B3: Title | C3: Severity | D3: Found by | E3: Found in | F3: Module | G3: Steps to reproduce | H3: Expected | I3: Actual | J3: Status | K3: Assignee | L3: Found date | M3: Closed date | N3: Fix commit
A4: B-001 | B4: (Sample) Login OTP timer count down sai | C4: P2 | D4: QA | E4: Dev | F4: Auth | G4: 1. Mở login 2. Nhập SĐT 3. Quan sát timer 5p | H4: Timer count down từ 5:00 → 0:00 | I4: Timer hiển thị 5:00 nhưng không count | J4: Open | K4: (dev) | L4: 2026-05-15

Sheet 5. Risks
A1: Risk Register
A3: Risk ID | B3: Description | C3: Category | D3: Probability | E3: Impact | F3: Severity | G3: Mitigation plan | H3: Owner | I3: Status | J3: Identified date | K3: Resolved date
A4: R-01 | B4: Isoft webhook contract chưa rõ. Thiếu field performed_by_user_id, recall_due_date | C4: External | D4: High | E4: High | F4: HIGH | G4: Anh contact Isoft trong 2 tuần. Plan B: build manual UI fallback (+5-10 ngày dev) | H4: Anh Phú | I4: Active | J4: 2026-05-05
A5: R-02 | B5: Zalo OA Verified chưa setup. Block Login OTP + Reminder + Recall | C5: External | D5: High | E5: High | F5: HIGH | G5: NP đăng ký Zalo OA ngay, 2-4 tuần verify + template approve | H5: Anh Phú | I5: Active | J5: 2026-05-05
A6: R-03 | B6: Database performance scale 100 đơn/ngày × 5 role × 6 events = 3000 records/day | C6: Technical | D6: Medium | E6: High | F6: MEDIUM-HIGH | G6: Index đúng (order_id, customer_id, cycle_id). Optimistic lock. Stress test 3x volume | H6: Dev lead | I6: Active | J6: 2026-05-05
A7: R-04 | B7: Money handling precision (luật kế toán VN). Sai số có thể vi phạm pháp lý | C7: Business | D7: Low | E7: High | F7: MEDIUM | G7: bigint VND, decimal(5,2) %HH, half-up rounding cuối. Đối soát Misa hằng tháng | H7: Dev lead | I7: Active | J7: 2026-05-05
A8: R-05 | B8: Auth security: OTP brute force, device hijack, account sharing | C8: Technical | D8: Medium | E8: High | F8: HIGH | G8: Rate limit OTP 3 lần/SĐT/15p. Device binding 1:1. Audit log đầy đủ | H8: Dev lead | I8: Active | J8: 2026-05-05
A9: R-06 | B9: Adjustment edit window 30 ngày clawback logic phức tạp | C9: Technical | D9: Medium | E9: Medium | F9: MEDIUM | G9: Test nhiều edge case: edit 1 lần, nhiều lần, sau payday, edit của edit | H9: Dev lead | I9: Active | J9: 2026-05-05
A10: R-07 | B10: Cross-month đơn HH timing confuse NV | C10: Operational | D10: Medium | E10: Low | F10: LOW-MEDIUM | G10: UI thêm cột "Kì gốc" trên pay slip. Diễm giải thích NV nếu cần | H10: PM | I10: Active | J10: 2026-05-05
A11: R-08 | B11: Customer follow-up phụ thuộc Isoft recall_due_date. Nếu Isoft không gửi → module non-functional | C11: External | D11: High | E11: Medium | F11: MEDIUM | G11: Manual workaround: NV/Hà gọi tay (out of app). Phase 2 add fallback Service default | H11: Anh Phú | I11: Active | J11: 2026-05-05

Sheet 6. Decisions
A1: Decisions Log
A3: ID | B3: Topic | C3: Context | D3: Decision | E3: Rationale | F3: Made by | G3: Date | H3: Spec Ref
A4: D-001 | B4: HH Formula | C4: Voucher có trừ khỏi base HH không | D4: net_profit = total_paid - total_cost. Voucher TRỪ khỏi base HH như BH | E4: Đơn giản, consistent với BH treatment. Voucher giảm doanh thu thực → giảm HH proportionally | F4: Anh Phú | G4: 2026-04-28 | H4: B4 R-1-1
A5: D-002 | B5: KT/CEO không HH | C5: KT trưởng và CEO có HH per đơn không | D5: KT (Diễm) ăn lương cứng, CEO ăn lợi nhuận. KHÔNG có HH per đơn | E5: OrderRoleAssignment chỉ populate Sale + TC + BS (3 roles có HH) | F5: Anh Phú | G5: 2026-04-28 | H5: B4 R-1-2
A6: D-003 | B6: Cap 10% intent | C6: App có enforce cap 10% net_profit không | D6: KHÔNG enforce. Chỉ awareness signal cho CEO review. Default NV full HH per formula | E6: Cut HH retroactive dễ gây mất lòng. Dùng cho process improvement | F6: Anh Phú | G6: 2026-05-01 | H6: B4 R-5-2
A7: D-004 | B7: Bonus formula | C7: Auto rule "Thưởng target tháng" formula | D7: bonus = HH gốc × bonus_pct × overshoot | E7: App KHÔNG quản lý lương cứng. Dùng HH gốc làm base | F7: Anh Phú | G7: 2026-05-01 | H7: B4 R-7-2
A8: D-005 | B8: Recall source | C8: Customer recall theo Service default hay y lệnh BS | D8: Chỉ consume recall_due_date từ Isoft webhook. KHÔNG có Service default fallback | E8: Trong y khoa, recall theo y lệnh BS per case. Đúng với reality | F8: Anh Phú | G8: 2026-05-01 | H8: B4 R-8-5
A9: D-006 | B9: Permission model | C9: Role permission hardcode hay configurable | D9: Phase 1 hardcode 5 role base. Phase 2 role-based config Sapo-style | E9: NP scale 5 NV không cần full role engine. Defer khi scale > 30 NV | F9: Anh Phú | G9: 2026-05-01 | H9: B4 R-9-2
A10: D-007 | B10: Auth method | C10: Password vs OTP | D10: SĐT + OTP qua Zalo OA, fallback SMS. KHÔNG có password | E10: OTP đơn giản hơn password (không reset, không quên). VN users quen OTP | F10: Anh Phú | G10: 2026-04-28 | H10: B5.2 S-Login
A11: D-008 | B11: Switch device 2nd factor | C11: Có cần email/voice confirm khi switch device không | D11: Bỏ 2nd factor. Chỉ OTP + notify CEO/TC | E11: NP scale 5 NV biết nhau. Cost dev voice/email cao, value thấp | F11: Anh Phú | G11: 2026-05-01 | H11: B5.2 §1.6
A12: D-009 | B12: Pay slip distribution | C12: App auto gửi pay slip hay KT tự lo | D12: KT trưởng (Diễm) tự lo pay slip distribution. App KHÔNG gửi | E12: App chỉ tính HH. Distribution là việc của Diễm (Zalo cá nhân, email tùy) | F12: Anh Phú | G12: 2026-05-01 | H12: B5.1 MS-12
A13: D-010 | B13: Lương cứng quản lý | C13: App quản lý lương cứng + HH hay chỉ HH | D13: App chỉ quản lý HH. Lương cứng quản lý ngoài (Misa) | E13: Scope rõ ràng. App HH = HH only | F13: Anh Phú | G13: 2026-05-01 | H13: B5.1 MS-12 Q-MS12-A
A14: D-011 | B14: Khiếu nại flow CEO involve | C14: CEO có duyệt khiếu nại CR không | D14: KHÔNG. KT (Diễm) quyết định alone (revert hoặc giữ reject) | E14: Operational decision của KT. CEO không micro-manage CR review | F14: Anh Phú | G14: 2026-04-28 | H14: B4 R-11-7
... A20: D-017 | B20: Bonus formula HH gốc vs lương cứng | C20: Bonus base lương cứng hay HH | D20: HH gốc × bonus_pct × overshoot | E20: App không quản lý lương cứng. HH gốc là available data | F20: Anh Phú | G20: 2026-05-01 | H20: B4 R-7-2

Sheet 7. Integrations
A1: External Integrations Status
A3: ISOFT (EMR/POS)
A4: Status | B4: ⚠️ Pending contract
A5: Owner | B5: Anh Phú
A6: Contact name | B6: (điền sau)
A7: Contact email | B7: (điền sau)
A8: Contact phone | B8: (điền sau)
A9: Webhook URL | B9: (điền sau khi setup)
A10: Authentication | B10: (TBD)
A11: Events supported | B11: (chờ confirm)
A12: Events cần | B12: order.checkin, order.exam_started, order.completed, order.refunded, order.cancelled, order.adjusted
A13: Last contact date | B13: (chưa)
A14: Next action | B14: Send template message từ PENDING-ITEMS section A
A15: Notes | B15: BLOCKER M4. Phụ thuộc payload đầy đủ (performed_by_user_id, recall_due_date)
A17: ZALO OA
A18: Status | B18: ⚠️ Not registered
A19: Owner | B19: Anh Phú
A20: OA ID | B20: (chưa có)
A21: Verified | B21: ❌ chưa
A22: Templates approved | B22: 0/4
A23: Template reminder_24h | B23: ❌ pending approve
A24: Template reminder_2h | B24: ❌ pending approve
A25: Template post_exam_thanks | B25: ❌ pending approve
A26: Template recall | B26: ❌ pending approve
A27: Setup steps | B27: 1. oa.zalo.me đăng ký 2. Upload giấy phép NP 3. Wait verify 1-2 tuần 4. Setup template 5. Wait template approve 1-2 tuần
A28: Next action | B28: NP đăng ký Zalo OA ngay tuần này
A29: Notes | B29: BLOCKER M1 (Login OTP) + M4 (Reminder)
A31: BANK
A32: Status | B32: ⏳ Awaiting NP info
A33: Owner | B33: Anh Phú
A34: Bank name | B34: (TBD)
A35: Account | B35: (TBD)
A36: Transfer file format | B36: Generic Excel (Diễm tự nhập tay)
A37: Notes | B37: Phase 2 có thể auto-upload theo bank format cụ thể
A39: MISA (kế toán)
A40: Status | B40: ✅ Out of scope
A41: Used by | B41: Diễm (KT)
A42: Integration | B42: ❌ KHÔNG integrate với app HH
A43: Workflow | B43: Diễm export Excel từ app HH → đối soát manual với Misa hằng tháng
A44: Notes | B44: Manual đối soát đủ cho NP scale 5 NV

Sheet 8. Timeline
A1: Project Timeline (24 weeks, 2 devs parallel)
A3: Milestone | B3: Name | C3: Goal | D3: Start week | E3: End week | F3: Duration (weeks) | G3: Gate criteria | H3: Status
A4: M1 | B4: Foundation | C4: Setup + Auth + Permission base | D4: 1 | E4: 4 | F4: 4 | G4: Demo login + permission cho anh Nguyên | H4: Not started
A5: M2 | B5: Core HH Engine | C5: Order lifecycle + HH calculation + CR workflow | D5: 5 | E5: 8 | F5: 4 | G5: Demo end-to-end "tạo đơn → ăn HH" | H5: Not started
A6: M3 | B6: Adjustment + Pay Cycle | C6: Adjustment workflow + Pay cycle + Excel export | D6: 9 | E6: 12 | F6: 4 | G6: Diễm test 1 cycle với data fake | H6: Not started
A7: M4 | B7: Integrations + Admin | C7: Isoft webhooks + Zalo OA + Admin screens full | D7: 13 | E7: 16 | F7: 4 | G7: Test integration Isoft + Zalo OA staging | H7: Not started
A8: M5 | B8: Customer Engagement + Polish | C8: Customer follow-up + Shift + Polish + Reuse | D8: 17 | E8: 20 | F8: 4 | G8: UAT internal team (Diễm + Hà + 1 NV) | H8: Not started
A9: M6 | B9: Pilot + Launch | C9: Testing + UAT + Pilot 2 tuần + Cutover + Hot-fix | D9: 21 | E9: 24 | F9: 4 | G9: Anh Nguyên approve go-live | H9: Not started
A10: Post | B10: Stabilization + Acceptance | C10: Run kì lương đầu, retro, plan phase 2, sign-off | D10: 25 | E10: 28 | F10: 4 | G10: Anh Nguyên ký nghiệm thu | H10: Not started
A12: Simplified Gantt (mỗi █ = 1 tuần)
A14: Milestone | B14: W1 | C14: W2 | D14: W3 | E14: W4 | F14: W5 | G14: W6 | H14: W7 | I14: W8 | J14: W9 | K14: W10 | L14: W11 | M14: W12 | N14: W13 | O14: W14 | P14: W15 | Q14: W16 | R14: W17 | S14: W18 | T14: W19 | U14: W20 | V14: W21 | W14: W22 | X14: W23 | Y14: W24 | Z14: W25 | AA14: W26 | AB14: W27 | AC14: W28
A15: M1 | B15: █ | C15: █ | D15: █ | E15: █
A16: M2 | F16: █ | G16: █ | H16: █ | I16: █
A17: M3 | J17: █ | K17: █ | L17: █ | M17: █
A18: M4 | N18: █ | O18: █ | P18: █ | Q18: █
A19: M5 | R19: █ | S19: █ | T19: █ | U19: █
A20: M6 | V20: █ | W20: █ | X20: █ | Y20: █
A21: Post | Z21: █ | AA21: █ | AB21: █ | AC21: █

Sheet 9. References
A1: References + Glossary
A3: AUDIT DOCS (16 files trong audit-docs/)
A4: File | B4: Description | C4: Status
A5: B1-bien-ban-context.md | B5: Context, business model, formula, entity dictionary | C5: FINAL v16
A6: B2-kich-ban-van-hanh.md | B6: 5 personas + workflow | C6: FINAL
A7: B2-2-bpmn-flowchart.md | B7: BPMN + state machines (Order, CR, Adjustment) | C7: FINAL v3
A8: B2-3-edge-cases.md | B8: 13 scenarios edge case + technical edge cases | C8: FINAL v2
A9: B2-4-pay-cycle.md | B9: Pay cycle ngày 5 chi tiết | C9: FINAL
A10: B3-screen-audit.md | B10: Audit 25 existing screens | C10: FINAL v2
A11: B4-business-rules.md | B11: ~75 business rules consolidate | C11: FINAL v3
A12: B5-1-screen-specs-batch-1.md | B12: 4 missing screens HIGH (MS-2, MS-9, MS-10, MS-12) | C12: FINAL v2
A13: B5-2-screen-specs-batch-2.md | B13: 3 screen rewrite (Login, Admin-Staff, Admin-Settings) | C13: FINAL
A14: B5-3-screen-specs-batch-3.md | B14: 3 screen update (Income, Order-Detail, Admin-Commission) | C14: FINAL
A15: B5-4-screen-specs-batch-4.md | B15: 3 new + 1 ranking (Shift, Auto Rule, Customer Follow-up) | C15: FINAL
... A20: NP-AppHH-MasterTracker.xlsx | B20: This file (master execution tracker) | C20: Living
A22: GLOSSARY
A23: Term | B23: Meaning
A24: NP | B24: Phòng khám Nguyên Phương
A25: HH | B25: Hoa Hồng (commission)
A26: CR | B26: CommissionRecord (record HH per role per đơn)
A27: KT | B27: Kế Toán (Diễm)
A28: TC | B28: Trưởng Ca (Hà)
A29: BS | B29: Bác Sĩ
A30: NV | B30: Nhân Viên (general)
A31: ĐD | B31: Điều Dưỡng
A32: ĐD-Sale | B32: Điều dưỡng kiêm Sale (1 role gộp)
A33: CEO | B33: Chief Executive Officer (anh Nguyên)
A34: SLA | B34: Service Level Agreement (cam kết chất lượng dịch vụ)
... A47: Phương án J | B47: Shift architecture: F (configurable shift) + extension hooks (priority + condition JSON)
A49: EXTERNAL RESOURCES
A50: Resource | B50: Link / Info
A51: Zalo OA Studio | B51: https://oa.zalo.me
A52: Isoft contact | B52: (điền sau khi anh Phú liên hệ)
A53: Bank info | B53: (điền sau khi NP confirm)
A54: Hosting / VPS | B54: (điền sau khi setup)
A55: Code repo | B55: (điền khi dev start)
A56: Staging URL | B56: (điền sau khi deploy)
A57: Production URL | B57: (điền sau khi launch)
A58: Project tracker (ClickUp) | B58: (điền link)
